'use client';

import React, { Component, ErrorInfo, ReactNode } from 'react';
import { AlertTriangle, RefreshCw } from 'lucide-react';

interface Props {
  children: ReactNode;
  fallback?: ReactNode;
  onError?: (error: Error, errorInfo: ErrorInfo) => void;
}

interface State {
  hasError: boolean;
  error?: Error;
  errorInfo?: ErrorInfo;
}

// Modern Error Boundary with better UX
export class ErrorBoundary extends Component<Props, State> {
  constructor(props: Props) {
    super(props);
    this.state = { hasError: false };
  }

  static getDerivedStateFromError(error: Error): State {
    return {
      hasError: true,
      error,
      errorInfo: undefined, // Will be set in componentDidCatch if needed
    };
  }

  componentDidCatch(error: Error, errorInfo: ErrorInfo) {
    console.error('üö® ErrorBoundary caught an error:', error, errorInfo);
    
    // Store error info directly in state via getDerivedStateFromError
    // Avoid setState here to prevent infinite loops
    
    // Call custom error handler if provided
    this.props.onError?.(error, errorInfo);

    // In production, you might want to send this to an error reporting service
    if (process.env.NODE_ENV === 'production') {
      // Example: Sentry.captureException(error, { contexts: { react: errorInfo } });
    }
  }

  handleRetry = () => {
    this.setState({ hasError: false, error: undefined, errorInfo: undefined });
  };

  render() {
    if (this.state.hasError) {
      // Custom fallback UI
      if (this.props.fallback) {
        return this.props.fallback;
      }

      // Default error UI with modern design
      return (
        <div className="min-h-[400px] flex items-center justify-center p-8">
          <div className="max-w-md w-full bg-white rounded-lg shadow-lg border border-red-200 p-6">
            <div className="flex items-center space-x-3 mb-4">
              <div className="flex-shrink-0">
                <AlertTriangle className="h-8 w-8 text-red-500" />
              </div>
              <div>
                <h3 className="text-lg font-semibold text-gray-900">
                  Algo deu errado
                </h3>
                <p className="text-sm text-gray-600">
                  Ocorreu um erro inesperado neste componente
                </p>
              </div>
            </div>

            {process.env.NODE_ENV === 'development' && this.state.error && (
              <div className="mb-4 p-3 bg-red-50 rounded border border-red-200">
                <p className="text-xs font-mono text-red-800 break-all">
                  {this.state.error.message}
                </p>
              </div>
            )}

            <div className="flex space-x-3">
              <button
                onClick={this.handleRetry}
                className="flex items-center space-x-2 px-4 py-2 bg-blue-600 text-white rounded-md hover:bg-blue-700 transition-colors duration-200"
              >
                <RefreshCw className="h-4 w-4" />
                <span>Tentar novamente</span>
              </button>
              
              <button
                onClick={() => window.location.reload()}
                className="px-4 py-2 bg-gray-200 text-gray-800 rounded-md hover:bg-gray-300 transition-colors duration-200"
              >
                Recarregar p√°gina
              </button>
            </div>
          </div>
        </div>
      );
    }

    return this.props.children;
  }
}

// Hook-based error boundary for functional components
export const useErrorHandler = () => {
  const [error, setError] = React.useState<Error | null>(null);

  const resetError = React.useCallback(() => {
    setError(null);
    errorThrown.current = false; // Reset the ref when error is cleared
  }, []);

  const captureError = React.useCallback((error: Error) => {
    console.error('üö® Error captured:', error);
    setError(error);
  }, []);

  const errorThrown = React.useRef(false);
  
  React.useEffect(() => {
    if (error && !errorThrown.current) {
      errorThrown.current = true;
      throw error;
    }
    // Reset ref when error is cleared
    if (!error && errorThrown.current) {
      errorThrown.current = false;
    }
  }, [error]); // Usando ref para evitar m√∫ltiplos throws do mesmo erro

  return { captureError, resetError };
};

// Async error boundary for handling promise rejections
export const AsyncErrorBoundary: React.FC<Props> = ({ children, ...props }) => {
  React.useEffect(() => {
    const handleUnhandledRejection = (event: PromiseRejectionEvent) => {
      console.error('üö® Unhandled promise rejection:', event.reason);
      // You can customize this behavior
    };

    window.addEventListener('unhandledrejection', handleUnhandledRejection);

    return () => {
      window.removeEventListener('unhandledrejection', handleUnhandledRejection);
    };
  }, []);

  return <ErrorBoundary {...props}>{children}</ErrorBoundary>;
};

export default ErrorBoundary;